<?xml version="1.0"?>
<robot name="peacetolero">
  <link name="base_link">
  	
    <visual>
      <geometry>
        <box size= "0.62 0.42 0.075"/>
      </geometry>
      <origin rpy="0 0 0" xyz="0 0 0"/>
    </visual>
  </link>
  
  <link name="front_left_wheel_link">
  	
  	<visual>
  		<geometry>
  			<cylinder length="0.1" radius="0.05"/>
  		</geometry>
  		<origin rpy="0 1.57075 1.57075" xyz="0 0 0"/>
  	</visual>
  </link>
	
	<joint name="base_to_front_left_wheel_joint" type="continuous">
    <parent link="base_link"/>
    <child link="front_left_wheel_link"/>
    <origin rpy="0 0 0" xyz="0.24 0.22 -0.09"/>
    <axis xyz="0 1 0"/>
  </joint>
  
  <link name="front_right_wheel_link">
  	
  	<visual>
  		<geometry>
  			<cylinder length="0.1" radius="0.05"/>
  		</geometry>
  		<origin rpy="0 1.57075 1.57075" xyz="0 0 0"/>
  	</visual>
  </link>
	
	<joint name="base_to_front_right_wheel_joint" type="continuous">
    <parent link="base_link"/>
    <child link="front_right_wheel_link"/>
    <origin rpy="0 0 0" xyz="0.24 -0.22 -0.09"/>
    <axis xyz="0 1 0"/>
  </joint>
  
  <link name="back_left_wheel_link">
  	
  	<visual>
  		<geometry>
  			<cylinder length="0.1" radius="0.05"/>
  		</geometry>
  		<origin rpy="0 1.57075 1.57075" xyz="0 0 0"/>
  	</visual>
  </link>
	
	<joint name="base_to_back_left_wheel_joint" type="continuous">
    <parent link="base_link"/>
    <child link="back_left_wheel_link"/>
    <origin rpy="0 0 0" xyz="-0.24 0.22 -0.09"/>
    <axis xyz="0 1 0"/>
  </joint>
  
  
  <link name="back_right_wheel_link">
  	
  	<visual>
  		<geometry>
  			<cylinder length="0.1" radius="0.05"/>
  		</geometry>
  		<origin rpy="0 1.57075 1.57075" xyz="0 0 0"/>
  	</visual>
  </link>
	
	<joint name="base_to_back_right_wheel_joint" type="continuous">
    <parent link="base_link"/>
    <child link="back_right_wheel_link"/>
    <origin rpy="0 0 0" xyz="-0.24 -0.22 -0.09"/>
    <axis xyz="0 1 0"/>
  </joint>
  
  <link name="camera_link">
  	
  	<visual>
  		<geometry>
  			<box size="0.04 0.08 0.02"/>
  		</geometry>
  		<origin rpy=" 0 0 0" xyz="0 0 0"/>
  	</visual>
  </link>
  
  <joint name="base_to_camera_joint" type="fixed">
  	<parent link="base_link"/>
  	<child link="camera_link"/>
  	<origin rpy=" 0 0 0" xyz="0.33 0 -0.02"/>
  </joint>
  
  <link name="lidar_link">
  	
  	<visual>
  		<geometry>
  			<cylinder length="0.04" radius="0.04"/>
  		</geometry>
  		<origin rpy=" 0 0 0" xyz="0 0 0"/>
  	</visual>
  </link>
  
  <joint name="base_to_lidar_joint" type="fixed">
  	<parent link="base_link"/>
  	<child link="lidar_link"/>
  	<origin rpy=" 0 0 0" xyz="0.35 0 0.02"/>
  </joint>
  
  <link name="base_arm">
  	<visual>
  	  <geometry>
  	  	<box size=" 0.09 0.02 0.03"/>
  	  </geometry>
  	 	<origin rpy=" 0 0 0" xyz="0 0 0"/>
  	</visual>
  </link>
  
  <joint name="base_to_arm" type="fixed">
  	<parent link="base_link"/>
  	<child link="base_arm"/>
  	<origin rpy="1.57075 0 1.57075" xyz=" -0.24 -0.255 0"/>
  </joint>
  
  <link name="arm_link1">
  <visual>
  	<geometry>
  		<box size="0.55 0.03 0.03"/>
  	</geometry>
  	<origin xyz=" 0.27 0 0" rpy="0 0 0"/>
  </visual>
  </link>
  
  <joint name="arm_base_to_link_1" type="revolute">
  	<parent link="base_arm"/>
  	<child link="arm_link1"/>
  	<origin rpy="0 1.57075 0" xyz="-0.06 0 0.53"/>
  	<axis xyz=" 0 0 1"/>
  	<limit lower="0" upper="1.57075" effort="1" velocity="20"/>
  	<joint_properties friction="0.0"/>
  </joint>
  
  <link name="arm_link2">
  	<visual>
  		<geometry>
  			<box size="0.20 0.03 0.03"/>
  		</geometry>
  		<origin xyz="-0.095 0 0" rpy="0 0 0"/>
  	</visual>
  </link>
  
  <joint name="link1_to_link2" type="revolute">
  	<parent link="arm_link1"/>
  	<child link="arm_link2"/>
  	<origin rpy=" 0 3.14159265 0" xyz=" 0.55 0 0"/>
  	<axis xyz="0 0 1"/>
  	<limit lower="-3.14159265" upper="3.14159265" effort="1" velocity="20"/>
  	<joint_properties friction="0.0"/>
  </joint>
  
  	
  	
  	
</robot>
